Workbook
Name A.TH.ER: #REF!
Name A.TH.ER: #REF!
Name A.TH.ER: #REF!
Name A.TH.ER: #REF!
Name A.TH.IN: #REF!
Name A.TH.IN: #REF!
Name A.TH.IN: #REF!
Name A.TH.IN: #REF!
Name A.TH.NT: #REF!
Name A.TH.NT: #REF!
Name A.TH.NT: #REF!
Name A.TH.NT: #REF!
Name A.TH.SR: #REF!
Name A.TH.SR: #REF!
Name A.TH.SR: #REF!
Name A.TH.SR: #REF!
Name A.TH.WA: #REF!
Name A.TH.WA: #REF!
Name A.TH.WA: #REF!
Name A.TH.WA: #REF!
Name C.TH.ER: #REF!
Name C.TH.ER: #REF!
Name C.TH.ER: #REF!
Name C.TH.ER: #REF!
Name C.TH.IN: #REF!
Name C.TH.IN: #REF!
Name C.TH.IN: #REF!
Name C.TH.IN: #REF!
Name C.TH.NT: #REF!
Name C.TH.NT: #REF!
Name C.TH.NT: #REF!
Name C.TH.NT: #REF!
Name C.TH.SR: #REF!
Name C.TH.SR: #REF!
Name C.TH.SR: #REF!
Name C.TH.SR: #REF!
Name C.TH.WA: #REF!
Name C.TH.WA: #REF!
Name C.TH.WA: #REF!
Name C.TH.WA: #REF!
Name Function: "RAaux. primary-supporting!$A1:$A5"
Name group.1: [0]!Function:GenBIATable
Name group.1: [0]!Function:GenBIATable
Name group.1: [0]!Function:GenBIATable
Name group.1: [0]!Function:GenBIATable
Name group.1: [0]!Function:GenBIATable
Name group.1: [0]!Function:GenBIATable
Name group.1: [0]!Function:GenBIATable
Name group.2: [0]!Function:GenBIATable
Name group.2: [0]!Function:GenBIATable
Name group.2: [0]!Function:GenBIATable
Name group.2: [0]!Function:GenBIATable
Name group.2: [0]!Function:GenBIATable
Name group.2: [0]!Function:GenBIATable
Name group.2: [0]!Function:GenBIATable
Name group.3: [0]!Function:GenBIATable
Name group.3: [0]!Function:GenBIATable
Name group.3: [0]!Function:GenBIATable
Name group.3: [0]!Function:GenBIATable
Name group.3: [0]!Function:GenBIATable

Sheet Threats catalogue
L2: Services | Q2: Software | Z2: Hardware | AG2: People | AJ2: Location
E3: Security Dimensions | H3: Source | J3: Likelihood | L3: SaaS | M3: IaaS | N3: PaaS | O3: Other | P3: Network | Q3: Firmware | R3: Middleware | X3: End user application | Z3: Processin/Storage | AF3: Portable | AG3: Decision maker | AH3: Normal User | AI3: Privileged user | AJ3: Physical Location | AK3: Utilities
B4: Type of threat | C4: ID | D4: Threat | E4: C | F4: I | G4: A | H4: D | I4: A | J4: E | K4: F | R4: Operating systems | S4: Web server | T4: Virtualisation layer | U4: Network stack | V4: Application server | W4: DBMS server | X4: In house developed | Y4: COTS | Z4: User device (portable) | AA4: User device (fixed) | AB4: Shared device (fixed) | AC4: Network equipment | AD4: Wired media | AE4: Wireless media
B5: Physical damage | C5: 1 | D5: Fire | F5: X | G5: X | H5: X | I5: X | J5: 4 | K5: 2 | O5: X | AA5: X | AB5: X | AC5: X | AD5: X | AF5: X | AJ5: X | AK5: X
C6: 2 | D6: Water damage | F6: X | G6: X | H6: X | I6: X | J6: 4 | K6: 2 | O6: X | AA6: X | AB6: X | AC6: X | AD6: X | AF6: X | AJ6: X | AK6: X
C7: 3 | D7: Pollution | F7: X | G7: X | I7: X | K7: 2 | O7: X | AA7: X | AB7: X | AC7: X | AF7: X | AK7: X
C8: 4 | D8: Major accident | F8: X | G8: X | H8: X | I8: X | J8: 2 | K8: 3 | O8: X | AA8: X | AB8: X | AC8: X | AD8: X | AF8: X | AJ8: X | AK8: X
C9: 5 | D9: Destruction of equipment or media | F9: X | G9: X | H9: X | I9: X | J9: 3 | K9: 3 | O9: X | Z9: X | AA9: X | AB9: X | AC9: X | AD9: X | AF9: X | AK9: X
C10: 6 | D10: Dust, corrosion, freezing | F10: X | G10: X | I10: X | K10: 2 | O10: X | Z10: X | AA10: X | AB10: X | AC10: X | AD10: X | AF10: X | AK10: X
B11: Natural events | C11: 7 | D11: Climatic phenomenon | F11: X | G11: X | I11: X | K11: 1 | O11: X | Z11: X | AA11: X | AB11: X | AC11: X | AD11: X | AF11: X | AJ11: X | AK11: X
C12: 8 | D12: Seismic phenomenon | F12: X | G12: X | I12: X | K12: 1 | Z12: X | AA12: X | AB12: X | AC12: X | AD12: X | AJ12: X | AK12: X
C13: 9 | D13: Volcanic phenomenon | F13: X | G13: X | I13: X | K13: 1 | Z13: X | AA13: X | AB13: X | AC13: X | AD13: X | AJ13: X | AK13: X
C14: 10 | D14: Meteorological phenomenon | F14: X | G14: X | I14: X | K14: 2 | AA14: X | AB14: X | AC14: X | AD14: X | AJ14: X | AK14: X
C15: 11 | D15: Flood | F15: X | G15: X | I15: X | K15: 1 | AA15: X | AB15: X | AC15: X | AJ15: X | AK15: X
B16: Loss of esential services | C16: 12 | D16: Failure of air-conditioning or water supply system | G16: X | H16: X | I16: X | J16: 3 | K16: 2 | AB16: X | AC16: X | AJ16: X | AK16: X
C17: 13 | D17: Loss of power supply | G17: X | I17: X | K17: 2 | AA17: X | AB17: X | AC17: X | AJ17: X | AK17: X
C18: 14 | D18: Failure of telecommunication equipment | G18: X | I18: X | K18: 2 | P18: X | AC18: X | AD18: x | AE18: x
B19: Disturbance due to radiation | C19: 15 | D19: Electromagnetion radiation | F19: X | G19: X | H19: X | I19: X | J19: 1 | K19: 1 | Z19: X | AA19: X | AB19: X | AC19: X | AD19: X | AE19: X | AK19: X
C20: 16 | D20: Thermal radiation | F20: X | G20: X | H20: X | I20: X | J20: 1 | K20: 1 | Z20: X | AA20: X | AB20: X | AC20: X | AK20: X
C21: 17 | D21: Electromagnetic pulses | F21: X | G21: X | H21: X | I21: X | J21: 2 | K21: 1 | AK21: X
B22: Compromise of information | C22: 18 | D22: Interception of compromising interface signals | E22: X | H22: X | J22: 2 | U22: X | Z22: X | AC22: X | AE22: X | AF22: X
C23: 19 | D23: Remote spying | E23: X | F23: X | G23: X | H23: X | J23: 2 | Z23: X | AA23: X | AG23: X | AH23: X | AI23: X
C24: 20 | D24: Eavesdropping | E24: X | H24: X | J24: 1 | P24: X | U24: X | Z24: X | AA24: X | AB24: X | AC24: X | AD24: X | AE24: X
C25: 21 | D25: Theft of media or documents | E25: X | H25: X | J25: 5 | Z25: X | AA25: X | AF25: X
C26: 22 | D26: Theft of equipment | E26: X | G26: X | H26: X | J26: 5 | Z26: X | AA26: X | AB26: X | AC26: X
C27: 23 | D27: Retrieval of recycled or discarded media | E27: X | H27: X | J27: 5 | Z27: X | AA27: X | AB27: X | AF27: X
C28: 24 | D28: Disclosure | E28: X | H28: X | I28: X | J28: 5 | K28: 3 | AG28: X | AH28: X | AI28: X
C29: 25 | D29: Data from untrustworthy sources | F29: X | G29: X | H29: X | I29: X | J29: 4 | K29: 4 | AG29: X | AH29: X | AI29: X
C30: 26 | D30: Tampering with hardware | E30: X | H30: X | J30: 3 | Z30: X | AA30: X | AB30: X
C31: 27 | D31: Tampering with software | E31: X | F31: X | G31: X | H31: X | I31: X | J31: 3 | K31: 4 | Q31: X | R31: X | S31: X | T31: X | V31: X | W31: X | X31: X | Y31: X
C32: 28 | D32: Position detection | E32: X | H32: X | J32: 2 | Z32: X
C33: 29 | D33: Advanced persistant threat | E33: X | F33: X | G33: X | H33: X | J33: 1 | Q33: X | R33: X | S33: X | T33: X | U33: X | V33: X | W33: X | X33: X | Y33: X | Z33: X | AA33: X | AB33: X | AC33: X | AD33: X | AE33: X | AG33: X | AH33: X | AI33: X
C34: 30 | D34: Social engineering | E34: X | G34: X | H34: X | J34: 3 | AG34: X | AH34: X | AI34: X
B35: Technical failures | C35: 31 | D35: Equipment failure | G35: X | I35: X | K35: 2 | Z35: X | AA35: X | AB35: X | AC35: X
C36: 32 | D36: Equipment malfunction | G36: X | I36: X | K36: 3
C37: 33 | D37: Saturation of the information system | G37: X | H37: X | J37: 4 | K37: 2 | P37: X | Q37: X | R37: X | S37: X | T37: X | U37: X | V37: X | W37: X | X37: X | Y37: X | Z37: X | AA37: X | AB37: X | AC37: X
C38: 34 | D38: Software malfunction | F38: X | G38: X | I38: X | K38: 3 | R38: X | S38: X | T38: X | V38: X | W38: X | X38: X | Y38: X | AG38: X | AH38: X | AI38: X
C39: 35 | D39: Breach of information system maintainability | G39: X | H39: X | I39: X | J39: 5 | K39: 2 | P39: X | Q39: X | R39: X | S39: X | T39: X | U39: X | V39: X | W39: X | X39: X | Y39: X | Z39: X | AA39: X | AB39: X | AC39: X | AD39: X | AF39: X
B40: Unauthorised Actions | C40: 36 | D40: Unauthorised use of equipment | E40: X | F40: X | G40: X | H40: X | J40: 3 | Q40: X | R40: X | S40: X | T40: X | V40: X | W40: X | X40: X | Y40: X | Z40: X | AA40: X | AB40: X | AC40: X
C41: 37 | D41: Fraudulent copying of software | E41: X | H41: X | J41: 4 | X41: X | Y41: X | AG41: X | AH41: X | AI41: X
...

Sheet Threats agent catalogue
A1: Type | B1: Subtype | C1: Description | D1: Power value
A2: External | B2: Nation States | C2: State-sponsored espionage activities related with intelligence or military groups. | D2: 5
B3: Cybercriminals | C3: Organised groups that commit illegal activities involving a computer or network-connected device, e.g.: crimes in which the computing device is the target; crimes in which the computer is used as a weapon. | D3: 4
B4: Cyber terrorism | C4: Hacker groups that, acting with terrorist objectives (ISIS cyber terrorist), use available anonymous tools and techniques or other illicit resources for communicating purposes, such as the deep web. | D4: 3
B5: Corporations | C5: Corporate-sponsored espionage activities. | D5: 3
B6: Hacktivists | C6: People that use the same tools and techniques as a hacker with the intention of disrupting services and bringing attention to a political or social cause. | D6: 2
B7: Script Kiddies | C7: Group of TA with technical knowledge but no financial, personal or ideological aspirations. They normally act as a consequence of their curiosity. | D7: 1
A8: Internal | B8: Partner/Contractor | C8: Organisation or individual (with no direct contractual link) that provides services to the target organisation. This may be a hosting facility, cloud provider, or any other service provider. | D8: 5
B9: Privileged insider | C9: Current employee with limited knowledge about system misuses or safeguards but with privileged access to sensitive information. | D9: 5
B10: Insider | C10: Current employee with limited knowledge about system misuses or safeguards and limited access to sensitive information. | D10: 3

Sheet SA types catalogue
A1: First level | B1: Second level | C1: Third level | D1: Examples
A2: Services | B2: IaaS | C2: N/A | D2: GoDaddy, DigitalOcean, Amazon Web Services, Google Cloud Platform, Microsoft Azure
B4: PaaS | C4: N/A | D4: GoDaddy, Amazon Web Services, Google Cloud Platform, Microsoft Azure
A6: Combination of supporting assets, including HW, SW and people that provide a service to the organisation for the same business objective or activity. | B6: SaaS | C6: N/A
B8: Network | C8: N/A | D8: ADSL, RDSI
B10: Third system | C10: N/A
A12: Software | B12: Firmware | C12: N/A | D12: EBIOS, UEFI
B14: Middleware | C14: Operating systems | D14: Windows, Mac OS, Linux
C16: Web server | D16: Tomcat
C18: Virtualisation layer | D18: VMware
C19: Network stack | D19: Open SSL, TCP IP
A20: Programmes and applications of the target system related to the processing, transmission and storage of primary assets. | C20: Application server | D20: PHP server, net server mobile application server, J2EE, WebSphere Application Server (WAS)
C22: DBMS server | D22: Oracle MySQL SQL
B24: End-user | C24: In house developed
B25: Application
C26: COTS | D26: Outlook, SAP,
A27: Hardware | B27: Processing/ | C27: User device (portable) | D27: Laptop, netbook, tablet, smartphone, smartcard, token
B28: Storage
C29: User device (fixed) | D29: Desktop, workstation
A31: Physical elements part of the Target System used for the processing, transmission and storage of primary assets (data and functions/services). | C31: Shared device (fixed) | D31: Server, Multi-purpose Device (networked printer/copier/scanner with storage)
B33: Network | C33: Network equipment | D33: Repeater, hub, bridge, switch, router, Wifi Access Point, Firewall, Firewall IDS, IPS Antivirus
C38: Wired media | D38: PSTN twisted pair, copper cable, UTP, coaxial cable, fibre optic
C40: Wireless Media | D40: Wifi 802.11, BlueTooth, IR, Radio, satellite, ADSL
B42: Portable | C42: N/A
A44: People | B44: Decision maker | C44: N/A | D44: Project Manager
A45: People and roles that use the target system or are involved in the processing, transmission and storage of primary assets.
B46: Normal user | C46: N/A | D46: Final user
B48: Privileged user | C48: N/A | D48: Database operator, system administrator,
B50: Physical location | C50: N/A | D50: Offices, premises, secure zone, administrative zone, computer room
A51: Location
A54: Infrastructures, offices and other premises related to the geographical location of the hardware and software managed by the organisation. | B54: Utilities | C54: N/A | D54: Power supply, Water supply, HVAC, Waste disposal, light, Furniture, Equipment

Sheet HOME
D5: INDEX
D6: Process 1 | E6: System Security Characterisation
D7: Process 2 | E7: Primary asset identification
E8: Asset valuation (BIA)
D9: Process 3 | E9: Supporting assets
D10: Process 4 | E10: System modelling
D11: Processes 5-6-7 | E11: Risk calculation
D12: Aux | E12: AuxThreats
E13: Likelihood-Frequency tables
E14: Measures cat
E15: Measures Register
E16: Mitigation factors table
E17: Security measures catalogue
B21: Disclaimer:
B22: The information found on this spreadsheet is intended to be used as a tool to facilitate the Risk Assessment process
B23: using the IT Risk Management Methodology (ITSRM2).
B25: Cells in gray are computed fields, therefore, they should not be modified
B26: Aux tables are used for filtering/sort and they feed other sheets, so, they should not be modified
B27: Adding rows or columns to the tables could modified the computing of the next steps into the process, for this reason
B28: it is not recommended to do so.

Sheet P1-System
B8: Organisation description
C10: Organisation name | D10: Ministry of Interior, MS A
C11: Business Objective | D11: To provide and efficient data access services for authorized government agencies (G2G),ensuring availability,confeditiality,integrity of citizens' records for critical e-gov services
B14: System description
C16: System name | D16: Citizen Data Registry Access Service
C17: Main purpose / function | D17: Provide read access to citizen data records for authorised government agencies via secure web services
C18: Information handled | D18: Citizen records including Name,Surname, ID Number,Contact Details etc.
C19: Users population | D19: Authorised government agencies in Member State A
B22: Identification of relevant constraints
C24: Constraints for the risk treatment
C25: Time | D25: Six Months
C26: Financial
C27: Technical | D27: Deployment of dedicated application server for web services
C28: Environmental
C29: Legal | D29: Comply with GDPR and National data protection laws
C30: Ease of use
C31: Other
C32: Constraints for the organization
C33: Political nature
C34: Strategic nature
C35: Budgetary
C36: Technical
C37: Other
B40: Specific regulations
C42: GDPR/Commission Decision 45/2001 Personally identifiable information (PII) | D42: Yes
C43: GDPR/Commission Decision 45/2001 Sensitive personal information | D43: No
C44: EUCI Top secret, secret, confidential, restricted | D44: No
B47: Identification of roles
C49: System owner | D49: Directorate-General of Public Service
C50: Data owner | D50: Directorate-General of Digital Society
C51: Information Security Officer | D51: Advises on IT security measures and monitors compliance
C52: DPC | D52: Handles Data protection compliance and audits
C53: Other | D53: System Manager,System Supplier, IT Service Provider
B56: Other stakeholders
C58: User Group 1
C59: User Group 2
C60: User Group 3
C61: User Group 4
B64: Identification of Mandatory Security Measures
C66: Security Policies and Standards | D66: The ministry adheres to general information security policies to ensure confeditiality,intergrity and availability of data. These include access control,data encryption and monitoring in alignment with established security frameworks suchs as ISO/IEC 27001
...

Sheet P2-Primary Assets
B4: Primary asset inventory
C6: ID | D6: Primary asset | E6: Type | F6: Description | G6: Owner | H6: Comments
C7: =IF(D7<>"",ROW()-6,"") -> 1 | D7: Citizen Data | E7: Data | F7: This dataset contains personal identifiable information (PII) of citizens | G7: Directorate-General of Digital Society
C8: =IF(D8<>"",ROW()-6,"") -> 2 | D8: Statistical Data | E8: Data | F8: Aggregated and anonymized demographic data derived from citizen records | G8: Directorate-General of Digital Society
C9: =IF(D9<>"",ROW()-6,"") -> 3 | D9: Read Access to Citizen Data | E9: Function | F9: This function enables authorized government agencies (G2G) to securely access individual citizen records as required by law. It ensures that access is limited to entities with proper authorization and safeguards the data's confidentiality, integrity, and availability | G9: Directorate-General of Public Services
C10: =IF(D10<>"",ROW()-6,"") -> 4 | D10: Provision of Statistical Data | E10: Function | F10: This function involves generating and delivering anonymized statistical data to the public (G2C) and businesses (G2B). It leverages citizen data to provide insights while protecting individual identities. | G10: Directorate-General of Public Services
C11: =IF(D11<>"",ROW()-6,"") -> 5 | D11: Access for Static information | E11: Function | F11: Public access to the Web Server for some static information - (G2C) | G11: Directorate-General of Public Services
C12: =IF(D12<>"",ROW()-6,"") -> 6 | D12: Read Access to Statistical Demographic Data | E12: Function | F12: Read access to statistical data provided only to authorized government agencies (required by law) - (G2G). | G12: Directorate-General of Digital Society
C13: =IF(D13<>"",ROW()-6,"")
C14: =IF(D14<>"",ROW()-6,"")
C15: =IF(D15<>"",ROW()-6,"")
C16: =IF(D16<>"",ROW()-6,"")
C17: =IF(D17<>"",ROW()-6,"")
C18: =IF(D18<>"",ROW()-6,"")
C19: =IF(D19<>"",ROW()-6,"")
C20: =IF(D20<>"",ROW()-6,"")
C21: =IF(D21<>"",ROW()-6,"")
C22: =IF(D22<>"",ROW()-6,"")
C23: =IF(D23<>"",ROW()-6,"")
C24: =IF(D24<>"",ROW()-6,"")
... C1004: =IF(D1004<>"",ROW()-6,"")

Sheet P2-Asset Valuation
G1: to fill
A4: Impact scenario | B4: Asset valuation: Business impact assessment (BIA)
C6: ID | D6: Impact scenario description | E6: Primary asset | F6: Dimension | G6: Impact type | H6: Effect | I6: Asset Value | J6: Code | K6: Value | L6: Potential adversary (Threat agent) | M6: Identified Potential Adversary | N6: Power | O6: Interest level | P6: Interest | Q6: Attractiveness | R6: Comments
C7: =IF(E7<>"",CONCATENATE("Bav",TEXT(ROW()-6,"000"),""),"") -> Bav001 | E7: Citizens' data | F7: Confidentiality | G7: Infringement of Laws and regulation | H7: Internal legal consequences that include fines and economic penalties for the EC | I7: =K7 -> 4 | J7: =IFERROR(VLOOKUP(G7,'Auxiliary data'!$B$96:$C$107,2,0),"") -> IT.LawReg | K7: =IFERROR(VLOOKUP(H7,'Auxiliary data'!$B$111:$C$212,2,0),"") -> 4 | L7: Cybercriminals | N7: =IFERROR(VLOOKUP(L7,'Auxiliary data'!$B$216:$C$224,2,0),"") -> 4 | O7: Low | P7: =IFERROR(VLOOKUP(O7,'Auxiliary data'!$B$228:$C$230,2,0),"") -> 1 | Q7: =IFERROR(N7+P7,"") -> 5
C8: =IF(E8<>"",CONCATENATE("Bav",TEXT(ROW()-6,"000"),""),"") -> Bav002 | E8: Providing citizen's data to third parties | F8: Availability | G8: Disruption of activities | H8: Is likely to cause disruption to activities within the EC and with impact on other organisations | I8: =K8 -> 5 | J8: =IFERROR(VLOOKUP(G8,'Auxiliary data'!$B$96:$C$107,2,0),"") -> IT.DisAct | K8: =IFERROR(VLOOKUP(H8,'Auxiliary data'!$B$111:$C$212,2,0),"") -> 5 | L8: Hacktivists | N8: =IFERROR(VLOOKUP(L8,'Auxiliary data'!$B$216:$C$224,2,0),"") -> 2 | O8: Medium | P8: =IFERROR(VLOOKUP(O8,'Auxiliary data'!$B$228:$C$230,2,0),"") -> 3 | Q8: =IFERROR(N8+P8,"") -> 5
C9: =IF(E9<>"",CONCATENATE("Bav",TEXT(ROW()-6,"000"),""),"") -> Bav003 | E9: TEst3 | I9: =K9 | J9: =IFERROR(VLOOKUP(G9,'Auxiliary data'!$B$96:$C$107,2,0),"") | K9: =IFERROR(VLOOKUP(H9,'Auxiliary data'!$B$111:$C$212,2,0),"") | N9: =IFERROR(VLOOKUP(L9,'Auxiliary data'!$B$216:$C$224,2,0),"") | P9: =IFERROR(VLOOKUP(O9,'Auxiliary data'!$B$228:$C$230,2,0),"") | Q9: =IFERROR(N9+P9,"")
C10: =IF(E10<>"",CONCATENATE("Bav",TEXT(ROW()-6,"000"),""),"") | I10: =K10 | J10: =IFERROR(VLOOKUP(G10,'Auxiliary data'!$B$96:$C$107,2,0),"") | K10: =IFERROR(VLOOKUP(H10,'Auxiliary data'!$B$111:$C$212,2,0),"") | N10: =IFERROR(VLOOKUP(L10,'Auxiliary data'!$B$216:$C$224,2,0),"") | P10: =IFERROR(VLOOKUP(O10,'Auxiliary data'!$B$228:$C$230,2,0),"") | Q10: =IFERROR(N10+P10,"")
C11: =IF(E11<>"",CONCATENATE("Bav",TEXT(ROW()-6,"000"),""),"") | I11: =K11 | J11: =IFERROR(VLOOKUP(G11,'Auxiliary data'!$B$96:$C$107,2,0),"") | K11: =IFERROR(VLOOKUP(H11,'Auxiliary data'!$B$111:$C$212,2,0),"") | N11: =IFERROR(VLOOKUP(L11,'Auxiliary data'!$B$216:$C$224,2,0),"") | P11: =IFERROR(VLOOKUP(O11,'Auxiliary data'!$B$228:$C$230,2,0),"") | Q11: =IFERROR(N11+P11,"")
C12: =IF(E12<>"",CONCATENATE("Bav",TEXT(ROW()-6,"000"),""),"") | I12: =K12 | J12: =IFERROR(VLOOKUP(G12,'Auxiliary data'!$B$96:$C$107,2,0),"") | K12: =IFERROR(VLOOKUP(H12,'Auxiliary data'!$B$111:$C$212,2,0),"") | N12: =IFERROR(VLOOKUP(L12,'Auxiliary data'!$B$216:$C$224,2,0),"") | P12: =IFERROR(VLOOKUP(O12,'Auxiliary data'!$B$228:$C$230,2,0),"") | Q12: =IFERROR(N12+P12,"")
C13: =IF(E13<>"",CONCATENATE("Bav",TEXT(ROW()-6,"000"),""),"") | I13: =K13 | J13: =IFERROR(VLOOKUP(G13,'Auxiliary data'!$B$96:$C$107,2,0),"") | K13: =IFERROR(VLOOKUP(H13,'Auxiliary data'!$B$111:$C$212,2,0),"") | N13: =IFERROR(VLOOKUP(L13,'Auxiliary data'!$B$216:$C$224,2,0),"") | P13: =IFERROR(VLOOKUP(O13,'Auxiliary data'!$B$228:$C$230,2,0),"") | Q13: =IFERROR(N13+P13,"")
C14: =IF(E14<>"",CONCATENATE("Bav",TEXT(ROW()-6,"000"),""),"") | I14: =K14 | J14: =IFERROR(VLOOKUP(G14,'Auxiliary data'!$B$96:$C$107,2,0),"") | K14: =IFERROR(VLOOKUP(H14,'Auxiliary data'!$B$111:$C$212,2,0),"") | N14: =IFERROR(VLOOKUP(L14,'Auxiliary data'!$B$216:$C$224,2,0),"") | P14: =IFERROR(VLOOKUP(O14,'Auxiliary data'!$B$228:$C$230,2,0),"") | Q14: =IFERROR(N14+P14,"")
C15: =IF(E15<>"",CONCATENATE("Bav",TEXT(ROW()-6,"000"),""),"") | I15: =K15 | J15: =IFERROR(VLOOKUP(G15,'Auxiliary data'!$B$96:$C$107,2,0),"") | K15: =IFERROR(VLOOKUP(H15,'Auxiliary data'!$B$111:$C$212,2,0),"") | N15: =IFERROR(VLOOKUP(L15,'Auxiliary data'!$B$216:$C$224,2,0),"") | P15: =IFERROR(VLOOKUP(O15,'Auxiliary data'!$B$228:$C$230,2,0),"") | Q15: =IFERROR(N15+P15,"")
C16: =IF(E16<>"",CONCATENATE("Bav",TEXT(ROW()-6,"000"),""),"") | I16: =K16 | J16: =IFERROR(VLOOKUP(G16,'Auxiliary data'!$B$96:$C$107,2,0),"") | K16: =IFERROR(VLOOKUP(H16,'Auxiliary data'!$B$111:$C$212,2,0),"") | N16: =IFERROR(VLOOKUP(L16,'Auxiliary data'!$B$216:$C$224,2,0),"") | P16: =IFERROR(VLOOKUP(O16,'Auxiliary data'!$B$228:$C$230,2,0),"") | Q16: =IFERROR(N16+P16,"")
C17: =IF(E17<>"",CONCATENATE("Bav",TEXT(ROW()-6,"000"),""),"") | I17: =K17 | J17: =IFERROR(VLOOKUP(G17,'Auxiliary data'!$B$96:$C$107,2,0),"") | K17: =IFERROR(VLOOKUP(H17,'Auxiliary data'!$B$111:$C$212,2,0),"") | N17: =IFERROR(VLOOKUP(L17,'Auxiliary data'!$B$216:$C$224,2,0),"") | P17: =IFERROR(VLOOKUP(O17,'Auxiliary data'!$B$228:$C$230,2,0),"") | Q17: =IFERROR(N17+P17,"")
C18: =IF(E18<>"",CONCATENATE("Bav",TEXT(ROW()-6,"000"),""),"") | I18: =K18 | J18: =IFERROR(VLOOKUP(G18,'Auxiliary data'!$B$96:$C$107,2,0),"") | K18: =IFERROR(VLOOKUP(H18,'Auxiliary data'!$B$111:$C$212,2,0),"") | N18: =IFERROR(VLOOKUP(L18,'Auxiliary data'!$B$216:$C$224,2,0),"") | P18: =IFERROR(VLOOKUP(O18,'Auxiliary data'!$B$228:$C$230,2,0),"") | Q18: =IFERROR(N18+P18,"")
C19: =IF(E19<>"",CONCATENATE("Bav",TEXT(ROW()-6,"000"),""),"") | I19: =K19 | J19: =IFERROR(VLOOKUP(G19,'Auxiliary data'!$B$96:$C$107,2,0),"") | K19: =IFERROR(VLOOKUP(H19,'Auxiliary data'!$B$111:$C$212,2,0),"") | N19: =IFERROR(VLOOKUP(L19,'Auxiliary data'!$B$216:$C$224,2,0),"") | P19: =IFERROR(VLOOKUP(O19,'Auxiliary data'!$B$228:$C$230,2,0),"") | Q19: =IFERROR(N19+P19,"")
C20: =IF(E20<>"",CONCATENATE("Bav",TEXT(ROW()-6,"000"),""),"") | I20: =K20 | J20: =IFERROR(VLOOKUP(G20,'Auxiliary data'!$B$96:$C$107,2,0),"") | K20: =IFERROR(VLOOKUP(H20,'Auxiliary data'!$B$111:$C$212,2,0),"") | N20: =IFERROR(VLOOKUP(L20,'Auxiliary data'!$B$216:$C$224,2,0),"") | P20: =IFERROR(VLOOKUP(O20,'Auxiliary data'!$B$228:$C$230,2,0),"") | Q20: =IFERROR(N20+P20,"")
C21: =IF(E21<>"",CONCATENATE("Bav",TEXT(ROW()-6,"000"),""),"") | I21: =K21 | J21: =IFERROR(VLOOKUP(G21,'Auxiliary data'!$B$96:$C$107,2,0),"") | K21: =IFERROR(VLOOKUP(H21,'Auxiliary data'!$B$111:$C$212,2,0),"") | N21: =IFERROR(VLOOKUP(L21,'Auxiliary data'!$B$216:$C$224,2,0),"") | P21: =IFERROR(VLOOKUP(O21,'Auxiliary data'!$B$228:$C$230,2,0),"") | Q21: =IFERROR(N21+P21,"")
... C1006: =IF(E1006<>"",CONCATENATE("Bav",TEXT(ROW()-6,"000"),""),"") | I1006: =K1006 | J1006: =IFERROR(VLOOKUP(G1006,'Auxiliary data'!$B$96:$C$107,2,0),"") | K1006: =IFERROR(VLOOKUP(H1006,'Auxiliary data'!$B$111:$C$212,2,0),"") | N1006: =IFERROR(VLOOKUP(L1006,'Auxiliary data'!$B$216:$C$224,2,0),"") | P1006: =IFERROR(VLOOKUP(O1006,'Auxiliary data'!$B$228:$C$230,2,0),"") | Q1006: =IFERROR(N1006+P1006,"")

Sheet P2-Asset Valuation (Manual)
B4: Asset valuation: Manual
C6: ID | D6: Description | E6: Primary asset | F6: Dimension | G6: Asset value
C7: =IF(E7<>"",CONCATENATE("Mav",TEXT(ROW()-6,"000"),""),"") -> Mav001 | E7: Citizen Data | F7: Confidentiality | G7: High
C8: =IF(E8<>"",CONCATENATE("Mav",TEXT(ROW()-6,"000"),""),"") -> Mav002 | E8: Citizen Data | F8: Integrity | G8: High
C9: =IF(E9<>"",CONCATENATE("Mav",TEXT(ROW()-6,"000"),""),"") -> Mav003 | E9: Citizen Data | F9: Availability | G9: High
C10: =IF(E10<>"",CONCATENATE("Mav",TEXT(ROW()-6,"000"),""),"") -> Mav004 | E10: Statistical Data | F10: Confidentiality | G10: Medium
C11: =IF(E11<>"",CONCATENATE("Mav",TEXT(ROW()-6,"000"),""),"") -> Mav005 | E11: Statistical Data | F11: Integrity | G11: Medium
C12: =IF(E12<>"",CONCATENATE("Mav",TEXT(ROW()-6,"000"),""),"") -> Mav006 | E12: Statistical Data | F12: Availability | G12: Medium
C13: =IF(E13<>"",CONCATENATE("Mav",TEXT(ROW()-6,"000"),""),"") -> Mav007 | E13: Read Access to Citizen Data | F13: Confidentiality | G13: High
C14: =IF(E14<>"",CONCATENATE("Mav",TEXT(ROW()-6,"000"),""),"") -> Mav008 | E14: Read Access to Citizen Data | F14: Integrity | G14: High
C15: =IF(E15<>"",CONCATENATE("Mav",TEXT(ROW()-6,"000"),""),"") -> Mav009 | E15: Read Access to Citizen Data | F15: Availability | G15: High
C16: =IF(E16<>"",CONCATENATE("Mav",TEXT(ROW()-6,"000"),""),"") -> Mav010 | E16: Provision of Statistical Data | F16: Confidentiality | G16: Low
C17: =IF(E17<>"",CONCATENATE("Mav",TEXT(ROW()-6,"000"),""),"") -> Mav011 | E17: Provision of Statistical Data | F17: Integrity | G17: Medium
C18: =IF(E18<>"",CONCATENATE("Mav",TEXT(ROW()-6,"000"),""),"") -> Mav012 | E18: Provision of Statistical Data | F18: Availability | G18: Medium
... C24: =IF(E24<>"",CONCATENATE("Mav",TEXT(ROW()-6,"000"),""),"") -> Mav018 | E24: Read Access to Statistical Demographic Data | F24: Availability | G24: Low
C25: =IF(E25<>"",CONCATENATE("Mav",TEXT(ROW()-6,"000"),""),"")
C26: =IF(E26<>"",CONCATENATE("Mav",TEXT(ROW()-6,"000"),""),"")
C27: =IF(E27<>"",CONCATENATE("Mav",TEXT(ROW()-6,"000"),""),"")
C28: =IF(E28<>"",CONCATENATE("Mav",TEXT(ROW()-6,"000"),""),"")
C29: =IF(E29<>"",CONCATENATE("Mav",TEXT(ROW()-6,"000"),""),"")
C30: =IF(E30<>"",CONCATENATE("Mav",TEXT(ROW()-6,"000"),""),"")
C31: =IF(E31<>"",CONCATENATE("Mav",TEXT(ROW()-6,"000"),""),"")
C32: =IF(E32<>"",CONCATENATE("Mav",TEXT(ROW()-6,"000"),""),"")
C33: =IF(E33<>"",CONCATENATE("Mav",TEXT(ROW()-6,"000"),""),"")
C34: =IF(E34<>"",CONCATENATE("Mav",TEXT(ROW()-6,"000"),""),"")
C35: =IF(E35<>"",CONCATENATE("Mav",TEXT(ROW()-6,"000"),""),"")
C36: =IF(E36<>"",CONCATENATE("Mav",TEXT(ROW()-6,"000"),""),"")
... C1007: =IF(E1007<>"",CONCATENATE("Mav",TEXT(ROW()-6,"000"),""),"")

Sheet P2-PA Attractiveness
B4: PA Attractiveness: Interest scenarios
C6: ID | D6: Description | E6: Primary asset | F6: Dimension | G6: Interest level | H6: Potential adversary (Threat agent) | I6: Power | J6: Atractiveness | K6: Interest level value
C7: =IF(E7<>"",CONCATENATE("Att",TEXT(ROW()-6,"000"),""),"") -> Att001 | E7: Citizen Data | F7: Confidentiality | G7: High | H7: Cybercriminals | I7: =IFERROR(VLOOKUP(H7,'Auxiliary data'!$B$216:$C$224,2,0),"") -> 4 | J7: =IFERROR(IF(AND(K7<>"",I7<>""),SUM(I7,K7),""),"") -> 9 | K7: =IFERROR(VLOOKUP(G7,'Auxiliary data'!$B$228:$C$230,2,0),"") -> 5
C8: =IF(E8<>"",CONCATENATE("Att",TEXT(ROW()-6,"000"),""),"") -> Att002 | E8: Citizen Data | F8: Confidentiality | G8: High | H8: Partner / Contractor | I8: =IFERROR(VLOOKUP(H8,'Auxiliary data'!$B$216:$C$224,2,0),"") -> 5 | J8: =IFERROR(IF(AND(K8<>"",I8<>""),SUM(I8,K8),""),"") -> 10 | K8: =IFERROR(VLOOKUP(G8,'Auxiliary data'!$B$228:$C$230,2,0),"") -> 5
C9: =IF(E9<>"",CONCATENATE("Att",TEXT(ROW()-6,"000"),""),"") -> Att003 | E9: Citizen Data | F9: Integrity | G9: High | H9: Privileged insider | I9: =IFERROR(VLOOKUP(H9,'Auxiliary data'!$B$216:$C$224,2,0),"") -> 5 | J9: =IFERROR(IF(AND(K9<>"",I9<>""),SUM(I9,K9),""),"") -> 10 | K9: =IFERROR(VLOOKUP(G9,'Auxiliary data'!$B$228:$C$230,2,0),"") -> 5
C10: =IF(E10<>"",CONCATENATE("Att",TEXT(ROW()-6,"000"),""),"") -> Att004 | E10: Citizen Data | F10: Availability | G10: High | H10: Privileged insider | I10: =IFERROR(VLOOKUP(H10,'Auxiliary data'!$B$216:$C$224,2,0),"") -> 5 | J10: =IFERROR(IF(AND(K10<>"",I10<>""),SUM(I10,K10),""),"") -> 10 | K10: =IFERROR(VLOOKUP(G10,'Auxiliary data'!$B$228:$C$230,2,0),"") -> 5
C11: =IF(E11<>"",CONCATENATE("Att",TEXT(ROW()-6,"000"),""),"") -> Att005 | E11: Statistical Data | F11: Confidentiality | G11: Medium | H11: Privileged insider | I11: =IFERROR(VLOOKUP(H11,'Auxiliary data'!$B$216:$C$224,2,0),"") -> 5 | J11: =IFERROR(IF(AND(K11<>"",I11<>""),SUM(I11,K11),""),"") -> 8 | K11: =IFERROR(VLOOKUP(G11,'Auxiliary data'!$B$228:$C$230,2,0),"") -> 3
C12: =IF(E12<>"",CONCATENATE("Att",TEXT(ROW()-6,"000"),""),"") -> Att006 | E12: Statistical Data | F12: Confidentiality | G12: Medium | H12: Hacktivists | I12: =IFERROR(VLOOKUP(H12,'Auxiliary data'!$B$216:$C$224,2,0),"") -> 2 | J12: =IFERROR(IF(AND(K12<>"",I12<>""),SUM(I12,K12),""),"") -> 5 | K12: =IFERROR(VLOOKUP(G12,'Auxiliary data'!$B$228:$C$230,2,0),"") -> 3
C13: =IF(E13<>"",CONCATENATE("Att",TEXT(ROW()-6,"000"),""),"") -> Att007 | E13: Statistical Data | F13: Confidentiality | G13: Medium | H13: Cybercriminals | I13: =IFERROR(VLOOKUP(H13,'Auxiliary data'!$B$216:$C$224,2,0),"") -> 4 | J13: =IFERROR(IF(AND(K13<>"",I13<>""),SUM(I13,K13),""),"") -> 7 | K13: =IFERROR(VLOOKUP(G13,'Auxiliary data'!$B$228:$C$230,2,0),"") -> 3
C14: =IF(E14<>"",CONCATENATE("Att",TEXT(ROW()-6,"000"),""),"") -> Att008 | E14: Statistical Data | F14: Integrity | G14: Medium | H14: Hacktivists | I14: =IFERROR(VLOOKUP(H14,'Auxiliary data'!$B$216:$C$224,2,0),"") -> 2 | J14: =IFERROR(IF(AND(K14<>"",I14<>""),SUM(I14,K14),""),"") -> 5 | K14: =IFERROR(VLOOKUP(G14,'Auxiliary data'!$B$228:$C$230,2,0),"") -> 3
C15: =IF(E15<>"",CONCATENATE("Att",TEXT(ROW()-6,"000"),""),"") -> Att009 | E15: Statistical Data | F15: Availability | G15: Medium | H15: Cybercriminals | I15: =IFERROR(VLOOKUP(H15,'Auxiliary data'!$B$216:$C$224,2,0),"") -> 4 | J15: =IFERROR(IF(AND(K15<>"",I15<>""),SUM(I15,K15),""),"") -> 7 | K15: =IFERROR(VLOOKUP(G15,'Auxiliary data'!$B$228:$C$230,2,0),"") -> 3
C16: =IF(E16<>"",CONCATENATE("Att",TEXT(ROW()-6,"000"),""),"") -> Att010 | E16: Read Access to Citizen Data | F16: Confidentiality | G16: High | H16: Privileged insider | I16: =IFERROR(VLOOKUP(H16,'Auxiliary data'!$B$216:$C$224,2,0),"") -> 5 | J16: =IFERROR(IF(AND(K16<>"",I16<>""),SUM(I16,K16),""),"") -> 10 | K16: =IFERROR(VLOOKUP(G16,'Auxiliary data'!$B$228:$C$230,2,0),"") -> 5
C17: =IF(E17<>"",CONCATENATE("Att",TEXT(ROW()-6,"000"),""),"") -> Att011 | E17: Read Access to Citizen Data | F17: Integrity | G17: Medium | H17: Privileged insider | I17: =IFERROR(VLOOKUP(H17,'Auxiliary data'!$B$216:$C$224,2,0),"") -> 5 | J17: =IFERROR(IF(AND(K17<>"",I17<>""),SUM(I17,K17),""),"") -> 8 | K17: =IFERROR(VLOOKUP(G17,'Auxiliary data'!$B$228:$C$230,2,0),"") -> 3
C18: =IF(E18<>"",CONCATENATE("Att",TEXT(ROW()-6,"000"),""),"") -> Att012 | E18: Read Access to Citizen Data | F18: Availability | G18: High | H18: Privileged insider | I18: =IFERROR(VLOOKUP(H18,'Auxiliary data'!$B$216:$C$224,2,0),"") -> 5 | J18: =IFERROR(IF(AND(K18<>"",I18<>""),SUM(I18,K18),""),"") -> 10 | K18: =IFERROR(VLOOKUP(G18,'Auxiliary data'!$B$228:$C$230,2,0),"") -> 5
... C32: =IF(E32<>"",CONCATENATE("Att",TEXT(ROW()-6,"000"),""),"") -> Att026 | E32: Read Access to Statistical Demographic Data | F32: Availability | G32: Medium | H32: Cybercriminals | I32: =IFERROR(VLOOKUP(H32,'Auxiliary data'!$B$216:$C$224,2,0),"") -> 4 | J32: =IFERROR(IF(AND(K32<>"",I32<>""),SUM(I32,K32),""),"") -> 7 | K32: =IFERROR(VLOOKUP(G32,'Auxiliary data'!$B$228:$C$230,2,0),"") -> 3
C33: =IF(E33<>"",CONCATENATE("Att",TEXT(ROW()-6,"000"),""),"") | I33: =IFERROR(VLOOKUP(H33,'Auxiliary data'!$B$216:$C$224,2,0),"") | J33: =IFERROR(IF(AND(K33<>"",I33<>""),SUM(I33,K33),""),"") | K33: =IFERROR(VLOOKUP(G33,'Auxiliary data'!$B$228:$C$230,2,0),"")
C34: =IF(E34<>"",CONCATENATE("Att",TEXT(ROW()-6,"000"),""),"") | I34: =IFERROR(VLOOKUP(H34,'Auxiliary data'!$B$216:$C$224,2,0),"") | J34: =IFERROR(IF(AND(K34<>"",I34<>""),SUM(I34,K34),""),"") | K34: =IFERROR(VLOOKUP(G34,'Auxiliary data'!$B$228:$C$230,2,0),"")
C35: =IF(E35<>"",CONCATENATE("Att",TEXT(ROW()-6,"000"),""),"") | I35: =IFERROR(VLOOKUP(H35,'Auxiliary data'!$B$216:$C$224,2,0),"") | J35: =IFERROR(IF(AND(K35<>"",I35<>""),SUM(I35,K35),""),"") | K35: =IFERROR(VLOOKUP(G35,'Auxiliary data'!$B$228:$C$230,2,0),"")
C36: =IF(E36<>"",CONCATENATE("Att",TEXT(ROW()-6,"000"),""),"") | I36: =IFERROR(VLOOKUP(H36,'Auxiliary data'!$B$216:$C$224,2,0),"") | J36: =IFERROR(IF(AND(K36<>"",I36<>""),SUM(I36,K36),""),"") | K36: =IFERROR(VLOOKUP(G36,'Auxiliary data'!$B$228:$C$230,2,0),"")
C37: =IF(E37<>"",CONCATENATE("Att",TEXT(ROW()-6,"000"),""),"") | I37: =IFERROR(VLOOKUP(H37,'Auxiliary data'!$B$216:$C$224,2,0),"") | J37: =IFERROR(IF(AND(K37<>"",I37<>""),SUM(I37,K37),""),"") | K37: =IFERROR(VLOOKUP(G37,'Auxiliary data'!$B$228:$C$230,2,0),"")
C38: =IF(E38<>"",CONCATENATE("Att",TEXT(ROW()-6,"000"),""),"") | I38: =IFERROR(VLOOKUP(H38,'Auxiliary data'!$B$216:$C$224,2,0),"") | J38: =IFERROR(IF(AND(K38<>"",I38<>""),SUM(I38,K38),""),"") | K38: =IFERROR(VLOOKUP(G38,'Auxiliary data'!$B$228:$C$230,2,0),"")
C39: =IF(E39<>"",CONCATENATE("Att",TEXT(ROW()-6,"000"),""),"") | I39: =IFERROR(VLOOKUP(H39,'Auxiliary data'!$B$216:$C$224,2,0),"") | J39: =IFERROR(IF(AND(K39<>"",I39<>""),SUM(I39,K39),""),"") | K39: =IFERROR(VLOOKUP(G39,'Auxiliary data'!$B$228:$C$230,2,0),"")
C40: =IF(E40<>"",CONCATENATE("Att",TEXT(ROW()-6,"000"),""),"") | I40: =IFERROR(VLOOKUP(H40,'Auxiliary data'!$B$216:$C$224,2,0),"") | J40: =IFERROR(IF(AND(K40<>"",I40<>""),SUM(I40,K40),""),"") | K40: =IFERROR(VLOOKUP(G40,'Auxiliary data'!$B$228:$C$230,2,0),"")
C41: =IF(E41<>"",CONCATENATE("Att",TEXT(ROW()-6,"000"),""),"") | I41: =IFERROR(VLOOKUP(H41,'Auxiliary data'!$B$216:$C$224,2,0),"") | J41: =IFERROR(IF(AND(K41<>"",I41<>""),SUM(I41,K41),""),"") | K41: =IFERROR(VLOOKUP(G41,'Auxiliary data'!$B$228:$C$230,2,0),"")
C42: =IF(E42<>"",CONCATENATE("Att",TEXT(ROW()-6,"000"),""),"") | I42: =IFERROR(VLOOKUP(H42,'Auxiliary data'!$B$216:$C$224,2,0),"") | J42: =IFERROR(IF(AND(K42<>"",I42<>""),SUM(I42,K42),""),"") | K42: =IFERROR(VLOOKUP(G42,'Auxiliary data'!$B$228:$C$230,2,0),"")
C43: =IF(E43<>"",CONCATENATE("Att",TEXT(ROW()-6,"000"),""),"") | I43: =IFERROR(VLOOKUP(H43,'Auxiliary data'!$B$216:$C$224,2,0),"") | J43: =IFERROR(IF(AND(K43<>"",I43<>""),SUM(I43,K43),""),"") | K43: =IFERROR(VLOOKUP(G43,'Auxiliary data'!$B$228:$C$230,2,0),"")
C44: =IF(E44<>"",CONCATENATE("Att",TEXT(ROW()-6,"000"),""),"") | I44: =IFERROR(VLOOKUP(H44,'Auxiliary data'!$B$216:$C$224,2,0),"") | J44: =IFERROR(IF(AND(K44<>"",I44<>""),SUM(I44,K44),""),"") | K44: =IFERROR(VLOOKUP(G44,'Auxiliary data'!$B$228:$C$230,2,0),"")
... C1001: =IF(E1001<>"",CONCATENATE("Att",TEXT(ROW()-6,"000"),""),"") | I1001: =IFERROR(VLOOKUP(H1001,'Auxiliary data'!$B$216:$C$224,2,0),"") | J1001: =IFERROR(IF(AND(K1001<>"",I1001<>""),SUM(I1001,K1001),""),"") | K1001: =IFERROR(VLOOKUP(G1001,'Auxiliary data'!$B$228:$C$230,2,0),"")
C1002: =IF(E1002<>"",CONCATENATE("Att",TEXT(ROW()-6,"000"),""),"") | I1002: =IFERROR(VLOOKUP(H1002,'Auxiliary data'!$B$216:$C$224,2,0),"") | J1002: =IFERROR(IF(AND(K1002<>"",I1002<>""),AVERAGE(I1002,K1002),""),"") | K1002: =IFERROR(VLOOKUP(G1002,'Auxiliary data'!$B$228:$C$230,2,0),"")

Sheet P2-Primary asset summary
B4: Primary Asset Summary
C6: ID | D6: Primary | E6: Dimension | F6: Asset value | G6: Method | H6: Attractiveness
C7: =IF(D7<>"",CONCATENATE("Pas",TEXT(ROW()-6,"000"),""),"") -> Pas001 | D7: Sensitive information | E7: Confidentiality | G7: BIA asset valuation
C8: =IF(D8<>"",CONCATENATE("Pas",TEXT(ROW()-6,"000"),""),"")
C9: =IF(D9<>"",CONCATENATE("Pas",TEXT(ROW()-6,"000"),""),"")
C10: =IF(D10<>"",CONCATENATE("Pas",TEXT(ROW()-6,"000"),""),"")
C11: =IF(D11<>"",CONCATENATE("Pas",TEXT(ROW()-6,"000"),""),"")
C12: =IF(D12<>"",CONCATENATE("Pas",TEXT(ROW()-6,"000"),""),"")
C13: =IF(D13<>"",CONCATENATE("Pas",TEXT(ROW()-6,"000"),""),"")
C14: =IF(D14<>"",CONCATENATE("Pas",TEXT(ROW()-6,"000"),""),"")
C15: =IF(D15<>"",CONCATENATE("Pas",TEXT(ROW()-6,"000"),""),"")
C16: =IF(D16<>"",CONCATENATE("Pas",TEXT(ROW()-6,"000"),""),"")
C17: =IF(D17<>"",CONCATENATE("Pas",TEXT(ROW()-6,"000"),""),"")
C18: =IF(D18<>"",CONCATENATE("Pas",TEXT(ROW()-6,"000"),""),"")
C19: =IF(D19<>"",CONCATENATE("Pas",TEXT(ROW()-6,"000"),""),"")
... C1007: =IF(D1007<>"",CONCATENATE("Pas",TEXT(ROW()-6,"000"),""),"")

Sheet Auxiliary data
B4: Aux Table 1
B5: Value | C5: Label
B6: 1 | C6: Very Low
B7: 2 | C7: Low
B8: 3 | C8: Medium
B9: 4 | C9: High
B10: 5 | C10: Very High
B12: Aux Table 2
B13: Label | C13: Value
B14: Very Low | C14: 1
B15: Low | C15: 2
B16: Medium | C16: 3
B17: High | C17: 4
B18: Very High | C18: 5
B20: Aux Table 3
B21: P.A. type
B22: Data
B23: Function
B25: Aux Table 4
B26: PA-SA Relation
B27: Store
B28: Process
B29: Transmit
B94: Aux table 8
B95: Impact type | C95: Code
B96: Financial loss (in %age of EC budget) | C96: IT.FinLoss | D96: < 0.001% | E96: 0.001% to 0.01% | F96: 0.01% to 0.05% | G96: 0.05% to 0.5% | H96: 0.5% to 2% | I96: 2% to 5% | J96: 5% to 30% | K96: 30% to 200% | L96: 200% to 1000% | M96: > 1000%
B97: Financial loss (based on 3.5G€ functioning budget of the EC) | C97: IT.FinLossEC | D97: < 50.000€ | E97: 50.000€ to 500.000€ | F97: 500.000€ to 2M€ | G97: 2M€ to 20M€ | H97: 20M€ to 100M€ | I97: 100M€ to 250M€ | J97: 250M€ to 1.5G€ | K97: 1.5G€ to 10G€ | L97: 10G€ to 50G€ | M97: > 50G€
B98: Delay in political decision / execution | C98: IT.DelPol | D98: One week or negligible delay | E98: Two weeks delay | F98: One month or moderate delay | G98: Two months delay | H98: 4 months delay | I98: Six months or significant delay | J98: One year delay | K98: Two years delay | L98: Four years delay | M98: Abandoned execution
B99: Damage political relations | C99: IT.DamPol | D99: Negligible damage to relations with Commission's partners. | E99: Moderate damage to relations with Commission's partners | F99: Consequential damage to political relation with Commission's partners | G99: Significant damages adversely affecting relations with Commission's partners | H99: Serious damages to relations with Commission's partners | I99: Significant damages affecting political relations in Member States | J99: Serious; raise tension or formal protest in some Member States | K99: Serious; raise tension or formal protest in several Member States | L99: Exceptionally grave; raise tension or formal protest in the EU and with others countries. | M99: would result in termination of relations between EU commission and member state or strategic alliance partner
B100: Result in critical intervention at political level (Council/Parliament) regarding the Commission's performance | C100: IT.PolInt | D100: Minimum intervention | E100: Minimum intervention with some resolution via alternative routine operations | F100: Moderate intervention | G100: Moderate intervention with substantial resolution via alternative routine operations | H100: Consequential, affects execution of political decisions | I100: Significant or impede important executions | J100: Serious, disrupt execution(s) | K100: Serious, disrupt execution(s) with disablement of execution of political decisions | L100: Exceptionally grave, abort critical execution(s) | M100: Stopping significant number of execution(s) with disablement of execution of political decisions
B101: Degradation of the Commission services (delayed delivery, %age of expected time) | C101: IT.DegServ | D101: 1% delay | E101: 10% delay | F101: 25% delay | G101: 50% delay
B102: Disruption of activities | C102: IT.DisAct | D102: Could cause disruption to activities within the EC | E102: Is likely to cause disruption to activities within the EC | F102: Is likely to cause disruption to activities within the EC and with impact on other organisations | G102: Is likely to have some impact to other organizations | H102: Is likely to cause major impact on other organisations | I102: Is likely to cause a serious impact on other organizations
B103: Damage to health and safety | C103: IT.HealSafe | D103: Minor injury(ies) to one individual | E103: Minor injury(ies) to some individuals | F103: More than minor injuries to several individuals | G103: Injuries to several individuals | H103: Major injuries or widespread injuries | I103: Life of individual(s) threatened | J103: Death of one individual | K103: Death of several individuals | L103: Permanent incapacitating injury or illness to many individuals that may lead to widespread loss of life | M103: Widespread loss of life
B104: Damage to Staff morale and productivity | C104: IT.MorProd | D104: Negligible damage to staff morale and productivity | E104: Minimum | F104: Moderate | G104: Consequential | H104: Significant | I104: Adversely affected | J104: Serious loss | K104: Complete loss
B105: Damage Organisation image and reputation | C105: IT.ImaRep | D105: Negligible damage to image and reputation | E105: Moderate negative publicity, limited to local/specific public | F105: Consequential, limited to local/specific public | G105: Moderate negative publicity, to public | H105: Consequential or limited to 3 EU countries | I105: Significant or limited to 5 EU countries | J105: More than serious, Europe wide or worldwide negative publ.
B106: Damage to Public Order | C106: IT.PubOrd | D106: negligible impact to public order, no disruption to community | E106: Limited or very localised protest | F106: Some alteration to public order | G106: Limited or very localised protest, endangering individual security or liberty | H106: Consequential, region wide protest, lightly injured people | I106: Demonstrations national effects or injured people | J106: Threaten stability | K106: Serious prejudice public order/extensive disruptions on national level | L106: Serious prejudice public order/extensive disruptions on several national levels | M106: widespread effects/ individual or loss of lifes
B107: Infringement of Laws and regulation | C107: IT.LawReg | D107: No relevant legal consequences for the EC | E107: No relevant legal consequences for the EC or third parties. | F107: Internal legal consequences for the EC | G107: Internal legal consequences that include fines and economic penalties for the EC | H107: Legal consequences that include sentences of imprisonment fo members of the EC | I107: Legal consequences that affect the formal constitution of the EC
B109: Aux table 9
B110: Description | C110: Value
B111: =D96 -> < 0.001% | C111: 1
...

Sheet AuxSA
B5: Aux table 5
B6: Supporting assets | C6: Level 1
B7: Software | C7: SA1.SW
B8: Software Data | C8: SA1.SWD
B9: Hardware | C9: SA1.HW
B10: Personnel | C10: SA1.PEO
B11: IT Service | C11: SA1.Services
B12: Location /Installation | C12: SA1.FAC
B14: Aux table 6
B15: Supporting assets | C15: Level 2 | D15: Level 1
B16: Data Center | C16: SA2.DC | D16: IT Service
B17: Network services | C17: SA2.ServNet
B18: Cloud services | C18: SA2.Cloud
B19: Standard service | C19: SA2.Stand
B20: User defined service | C20: SA2.UserDef
B21: Data container | C21: SA2.DatCon | D21: Software Data
B22: Application data | C22: SA2.AppDat
B23: Security data | C23: SA2.SecDat
B24: Firmware | C24: SA2.Firm | D24: Software
B25: Middleware | C25: SA2.Middle
B26: End-user application | C26: SA2.EUAPP
B27: End-point | C27: SA2.EP | D27: Hardware
B28: Server | C28: SA2.Svr
B29: Network node | C29: SA2.NetNode
B30: Network media | C30: SA2.NetMed
B31: Data media | C31: SA2.DatMed
B32: Peripherals | C32: SA2.Per
B33: Service provider | C33: SA2.SerProv | D33: Personnel
B34: Normal user | C34: SA2.NormUs
B35: Priviliged user / Manager | C35: SA2.PriUs
B36: System supplier | C36: SA2.SysSup
B37: Area | C37: SA2.Area | D37: Location /Installation
B38: Building | C38: SA2.Buil
B39: Room | C39: SA2.Room
B40: Container | C40: SA2.Cont
B41: Mobile platform | C41: SA2.MobPla
B43: Aux table 7
B44: Supporting assets | C44: Level 2 | D44: Level 1
B45: Hosting | C45: Data Center | D45: =D16 -> IT Service
B46: Housing
...

Sheet P3-Supporting assets
D2: Number of primary assets
B3: Supporting assets Inventory
C5: ID | D5: Supporting asset | E5: Type | H5: Description | I5: Owner | L5: Comments
E6: Level 1 | F6: Level 2 | G6: Level 3 | J6: L2-code | K6: L3-code
C7: =IF(D7<>"",ROW()-6,"") -> 1 | D7: New Web Server | E7: Hardware | F7: Server | G7: N/A | J7: =VLOOKUP(E7,SAlevel1map,2,0) -> SA1.HW | K7: =VLOOKUP(F7,SALevel2map,2,0) -> SA2.Svr
C8: =IF(D8<>"",ROW()-6,"") -> 2 | D8: Application Server | E8: Hardware | F8: Server | G8: N/A | J8: =VLOOKUP(E8,SAlevel1map,2,0) -> SA1.HW | K8: =VLOOKUP(F8,SALevel2map,2,0) -> SA2.Svr
C9: =IF(D9<>"",ROW()-6,"") -> 3 | D9: New Database Server | E9: Hardware | F9: Server | G9: N/A | J9: =VLOOKUP(E9,SAlevel1map,2,0) -> SA1.HW | K9: =VLOOKUP(F9,SALevel2map,2,0) -> SA2.Svr
C10: =IF(D10<>"",ROW()-6,"") -> 4 | D10: Router | E10: Hardware | F10: Network node | G10: N/A | J10: =VLOOKUP(E10,SAlevel1map,2,0) -> SA1.HW | K10: =VLOOKUP(F10,SALevel2map,2,0) -> SA2.NetNode
C11: =IF(D11<>"",ROW()-6,"") -> 5 | D11: External Firewall | E11: Hardware | F11: Network node | G11: N/A | J11: =VLOOKUP(E11,SAlevel1map,2,0) -> SA1.HW | K11: =VLOOKUP(F11,SALevel2map,2,0) -> SA2.NetNode
C12: =IF(D12<>"",ROW()-6,"") -> 6 | D12: Core Switch | E12: Hardware | F12: Network node | G12: N/A | J12: =VLOOKUP(E12,SAlevel1map,2,0) -> SA1.HW | K12: =VLOOKUP(F12,SALevel2map,2,0) -> SA2.NetNode
C13: =IF(D13<>"",ROW()-6,"") -> 7 | D13: New Web Server | E13: Software | F13: Middleware | G13: Web Server | J13: =VLOOKUP(E13,SAlevel1map,2,0) -> SA1.SW | K13: =VLOOKUP(F13,SALevel2map,2,0) -> SA2.Middle
C14: =IF(D14<>"",ROW()-6,"") -> 8 | D14: Application Server | E14: Software | F14: Middleware | G14: Application server | J14: =VLOOKUP(E14,SAlevel1map,2,0) -> SA1.SW | K14: =VLOOKUP(F14,SALevel2map,2,0) -> SA2.Middle
C15: =IF(D15<>"",ROW()-6,"") -> 9 | D15: New Database Server | E15: Software | F15: Middleware | G15: DB Server | J15: =VLOOKUP(E15,SAlevel1map,2,0) -> SA1.SW | K15: =VLOOKUP(F15,SALevel2map,2,0) -> SA2.Middle
C16: =IF(D16<>"",ROW()-6,"") -> 10 | D16: Router | E16: IT Service | F16: Network services | G16: N/A | J16: =VLOOKUP(E16,SAlevel1map,2,0) -> SA1.Services | K16: =VLOOKUP(F16,SALevel2map,2,0) -> SA2.ServNet
C17: =IF(D17<>"",ROW()-6,"") -> 11 | D17: New Database Server | E17: Software Data | F17: Data container | G17: N/A | J17: =VLOOKUP(E17,SAlevel1map,2,0) -> SA1.SWD | K17: =VLOOKUP(F17,SALevel2map,2,0) -> SA2.DatCon
C18: =IF(D18<>"",ROW()-6,"") -> 12 | D18: Application Server | E18: Software Data | F18: Application data | G18: N/A | J18: =VLOOKUP(E18,SAlevel1map,2,0) -> SA1.SWD | K18: =VLOOKUP(F18,SALevel2map,2,0) -> SA2.AppDat
... C24: =IF(D24<>"",ROW()-6,"") -> 18 | D24: Statistical Data Provision Service | E24: IT Service | F24: User defined service | G24: N/A | J24: =VLOOKUP(E24,SAlevel1map,2,0) -> SA1.Services | K24: =VLOOKUP(F24,SALevel2map,2,0) -> SA2.UserDef
C25: =IF(D25<>"",ROW()-6,"") | J25: =VLOOKUP(E25,SAlevel1map,2,0) -> #N/A | K25: =VLOOKUP(F25,SALevel2map,2,0) -> #N/A
C26: =IF(D26<>"",ROW()-6,"") | J26: =VLOOKUP(E26,SAlevel1map,2,0) -> #N/A | K26: =VLOOKUP(F26,SALevel2map,2,0) -> #N/A
C27: =IF(D27<>"",ROW()-6,"") | J27: =VLOOKUP(E27,SAlevel1map,2,0) -> #N/A | K27: =VLOOKUP(F27,SALevel2map,2,0) -> #N/A
C28: =IF(D28<>"",ROW()-6,"") | J28: =VLOOKUP(E28,SAlevel1map,2,0) -> #N/A | K28: =VLOOKUP(F28,SALevel2map,2,0) -> #N/A
C29: =IF(D29<>"",ROW()-6,"") | J29: =VLOOKUP(E29,SAlevel1map,2,0) -> #N/A | K29: =VLOOKUP(F29,SALevel2map,2,0) -> #N/A
C30: =IF(D30<>"",ROW()-6,"") | J30: =VLOOKUP(E30,SAlevel1map,2,0) -> #N/A | K30: =VLOOKUP(F30,SALevel2map,2,0) -> #N/A
C31: =IF(D31<>"",ROW()-6,"") | J31: =VLOOKUP(E31,SAlevel1map,2,0) -> #N/A | K31: =VLOOKUP(F31,SALevel2map,2,0) -> #N/A
C32: =IF(D32<>"",ROW()-6,"") | J32: =VLOOKUP(E32,SAlevel1map,2,0) -> #N/A | K32: =VLOOKUP(F32,SALevel2map,2,0) -> #N/A
C33: =IF(D33<>"",ROW()-6,"") | J33: =VLOOKUP(E33,SAlevel1map,2,0) -> #N/A | K33: =VLOOKUP(F33,SALevel2map,2,0) -> #N/A
C34: =IF(D34<>"",ROW()-6,"") | J34: =VLOOKUP(E34,SAlevel1map,2,0) -> #N/A | K34: =VLOOKUP(F34,SALevel2map,2,0) -> #N/A
C35: =IF(D35<>"",ROW()-6,"") | J35: =VLOOKUP(E35,SAlevel1map,2,0) -> #N/A | K35: =VLOOKUP(F35,SALevel2map,2,0) -> #N/A
C36: =IF(D36<>"",ROW()-6,"") | J36: =VLOOKUP(E36,SAlevel1map,2,0) -> #N/A | K36: =VLOOKUP(F36,SALevel2map,2,0) -> #N/A
... C1006: =IF(D1006<>"",ROW()-6,"") | J1006: =VLOOKUP(E1006,SAlevel1map,2,0) -> #N/A | K1006: =VLOOKUP(F1006,SALevel2map,2,0) -> #N/A

Sheet P4-System Modelling
B4: Supporting asset - Primary asset relation
B6: Supporting | Primary | C6: Citizen Data | D6: Statistical Data | E6: Read Access to Citizen Data | F6: Provision of Statistical Data | G6: Access for Static information | H6: Read Access to Statistical Demographic Data | M6: Comments
B7: New Web Server | C7: X | D7: X | G7: X
B8: Application Server | C8: X | D8: X | H8: X
B9: New Database Server | C9: X | D9: X | E9: X | F9: X | H9: X
B10: Router | E10: X | F10: X | G10: X | H10: X
B11: External Firewall | E11: X | F11: X | G11: X | H11: X
B12: Core Switch | E12: X | F12: X | G12: X | H12: X
B13: Web Hosting Services | C13: X | D13: X | E13: X | F13: X | G13: X | H13: X
B14: Citizen Data Provision Service | C14: X | E14: X
B15: Internet Service | C15: X | D15: X | E15: X | F15: X | G15: X | H15: X
B16: Statistical Data Provision Service | D16: X | F16: X | H16: X

Sheet P4-System Modelling Values
B4: Supporting asset - Primary asset relation
B6: Supporting | Primary | D6: Prim1 | E6: Prim2 | F6: Prim3 | G6: Prim4 | H6: Prim5 | I6: Prim6 | J6: Prim7 | K6: Prim8 | L6: Prim9 | M6: Prim10 | N6: Accumulated value | P6: Comments
B7: SUP1 | C7: Dimension | D7: X | H7: X | I7: X | J7: X | N7: Dimension | O7: Value
C8: C | D8: {=IF(D7<>"",MAX(IF('P2-Asset Valuation'!$E$7:$E$1006=$D$6,IF('P2-Asset Valuation'!$F$7:$F$1006="Confidentiality",'P2-Asset Valuation'!$I$7:$I$1006))),"")} -> 0 | E8: {=IF(E7<>"",MAX(IF('P2-Asset Valuation'!$E$7:$E$1006=$E$6,IF('P2-Asset Valuation'!$F$7:$F$1006="Confidentiality",'P2-Asset Valuation'!$I$7:$I$1006))),"")} | F8: {=IF(F7<>"",MAX(IF('P2-Asset Valuation'!$E$7:$E$1006=$F$6,IF('P2-Asset Valuation'!$F$7:$F$1006="Confidentiality",'P2-Asset Valuation'!$I$7:$I$1006))),"")} | G8: {=IF(G7<>"",MAX(IF('P2-Asset Valuation'!$E$7:$E$1006=$G$6,IF('P2-Asset Valuation'!$F$7:$F$1006="Confidentiality",'P2-Asset Valuation'!$I$7:$I$1006))),"")} | H8: {=IF(H7<>"",MAX(IF('P2-Asset Valuation'!$E$7:$E$1006=$H$6,IF('P2-Asset Valuation'!$F$7:$F$1006="Confidentiality",'P2-Asset Valuation'!$I$7:$I$1006))),"")} -> 0 | I8: {=IF(I7<>"",MAX(IF('P2-Asset Valuation'!$E$7:$E$1006=$I$6,IF('P2-Asset Valuation'!$F$7:$F$1006="Confidentiality",'P2-Asset Valuation'!$I$7:$I$1006))),"")} -> 0 | J8: {=IF(J7<>"",MAX(IF('P2-Asset Valuation'!$E$7:$E$1006=$J$6,IF('P2-Asset Valuation'!$F$7:$F$1006="Confidentiality",'P2-Asset Valuation'!$I$7:$I$1006))),"")} -> 0 | K8: {=IF(K7<>"",MAX(IF('P2-Asset Valuation'!$E$7:$E$1006=$K$6,IF('P2-Asset Valuation'!$F$7:$F$1006="Confidentiality",'P2-Asset Valuation'!$I$7:$I$1006))),"")} | L8: {=IF(L7<>"",MAX(IF('P2-Asset Valuation'!$E$7:$E$1006=$L$6,IF('P2-Asset Valuation'!$F$7:$F$1006="Confidentiality",'P2-Asset Valuation'!$I$7:$I$1006))),"")} | M8: {=IF(M7<>"",MAX(IF('P2-Asset Valuation'!$E$7:$E$1006=$M$6,IF('P2-Asset Valuation'!$F$7:$F$1006="Confidentiality",'P2-Asset Valuation'!$I$7:$I$1006))),"")} | N8: C | O8: =SUM(D8:M8) -> 0
C9: I | D9: {=IF(D7<>"",MAX(IF('P2-Asset Valuation'!$E$7:$E$1006=$D$6,IF('P2-Asset Valuation'!$F$7:$F$1006="Integrity",'P2-Asset Valuation'!$I$7:$I$1006))),"")} -> 0 | E9: {=IF(E7<>"",MAX(IF('P2-Asset Valuation'!$E$7:$E$1006=$E$6,IF('P2-Asset Valuation'!$F$7:$F$1006="Integrity",'P2-Asset Valuation'!$I$7:$I$1006))),"")} | F9: {=IF(F7<>"",MAX(IF('P2-Asset Valuation'!$E$7:$E$1006=$F$6,IF('P2-Asset Valuation'!$F$7:$F$1006="Integrity",'P2-Asset Valuation'!$I$7:$I$1006))),"")} | G9: {=IF(G7<>"",MAX(IF('P2-Asset Valuation'!$E$7:$E$1006=$G$6,IF('P2-Asset Valuation'!$F$7:$F$1006="Integrity",'P2-Asset Valuation'!$I$7:$I$1006))),"")} | H9: {=IF(H7<>"",MAX(IF('P2-Asset Valuation'!$E$7:$E$1006=$H$6,IF('P2-Asset Valuation'!$F$7:$F$1006="Integrity",'P2-Asset Valuation'!$I$7:$I$1006))),"")} -> 0 | I9: {=IF(I7<>"",MAX(IF('P2-Asset Valuation'!$E$7:$E$1006=$I$6,IF('P2-Asset Valuation'!$F$7:$F$1006="Integrity",'P2-Asset Valuation'!$I$7:$I$1006))),"")} -> 0 | J9: {=IF(J7<>"",MAX(IF('P2-Asset Valuation'!$E$7:$E$1006=$J$6,IF('P2-Asset Valuation'!$F$7:$F$1006="Integrity",'P2-Asset Valuation'!$I$7:$I$1006))),"")} -> 0 | K9: {=IF(K7<>"",MAX(IF('P2-Asset Valuation'!$E$7:$E$1006=$K$6,IF('P2-Asset Valuation'!$F$7:$F$1006="Integrity",'P2-Asset Valuation'!$I$7:$I$1006))),"")} | L9: {=IF(L7<>"",MAX(IF('P2-Asset Valuation'!$E$7:$E$1006=$L$6,IF('P2-Asset Valuation'!$F$7:$F$1006="Integrity",'P2-Asset Valuation'!$I$7:$I$1006))),"")} | M9: {=IF(M7<>"",MAX(IF('P2-Asset Valuation'!$E$7:$E$1006=$M$6,IF('P2-Asset Valuation'!$F$7:$F$1006="Integrity",'P2-Asset Valuation'!$I$7:$I$1006))),"")} | N9: I | O9: =SUM(D9:M9) -> 0
C10: A | D10: {=IF(D7<>"",MAX(IF('P2-Asset Valuation'!$E$7:$E$1006=$D$6,IF('P2-Asset Valuation'!$F$7:$F$1006="Availability",'P2-Asset Valuation'!$I$7:$I$1006))),"")} -> 0 | E10: {=IF(E7<>"",MAX(IF('P2-Asset Valuation'!$E$7:$E$1006=$E$6,IF('P2-Asset Valuation'!$F$7:$F$1006="Availability",'P2-Asset Valuation'!$I$7:$I$1006))),"")} | F10: {=IF(F7<>"",MAX(IF('P2-Asset Valuation'!$E$7:$E$1006=$F$6,IF('P2-Asset Valuation'!$F$7:$F$1006="Availability",'P2-Asset Valuation'!$I$7:$I$1006))),"")} | G10: {=IF(G7<>"",MAX(IF('P2-Asset Valuation'!$E$7:$E$1006=$G$6,IF('P2-Asset Valuation'!$F$7:$F$1006="Availability",'P2-Asset Valuation'!$I$7:$I$1006))),"")} | H10: {=IF(H7<>"",MAX(IF('P2-Asset Valuation'!$E$7:$E$1006=$H$6,IF('P2-Asset Valuation'!$F$7:$F$1006="Availability",'P2-Asset Valuation'!$I$7:$I$1006))),"")} -> 0 | I10: {=IF(I7<>"",MAX(IF('P2-Asset Valuation'!$E$7:$E$1006=$I$6,IF('P2-Asset Valuation'!$F$7:$F$1006="Availability",'P2-Asset Valuation'!$I$7:$I$1006))),"")} -> 0 | J10: {=IF(J7<>"",MAX(IF('P2-Asset Valuation'!$E$7:$E$1006=$J$6,IF('P2-Asset Valuation'!$F$7:$F$1006="Availability",'P2-Asset Valuation'!$I$7:$I$1006))),"")} -> 0 | K10: {=IF(K7<>"",MAX(IF('P2-Asset Valuation'!$E$7:$E$1006=$K$6,IF('P2-Asset Valuation'!$F$7:$F$1006="Availability",'P2-Asset Valuation'!$I$7:$I$1006))),"")} | L10: {=IF(L7<>"",MAX(IF('P2-Asset Valuation'!$E$7:$E$1006=$L$6,IF('P2-Asset Valuation'!$F$7:$F$1006="Availability",'P2-Asset Valuation'!$I$7:$I$1006))),"")} | M10: {=IF(M7<>"",MAX(IF('P2-Asset Valuation'!$E$7:$E$1006=$M$6,IF('P2-Asset Valuation'!$F$7:$F$1006="Availability",'P2-Asset Valuation'!$I$7:$I$1006))),"")} | N10: A | O10: =SUM(D10:M10) -> 0
B11: Sup2 | C11: Dimension | E11: X | K11: X | L11: X | N11: Dimension | O11: Value
C12: C | D12: {=IF(D11<>"",MAX(IF('P2-Asset Valuation'!$E$7:$E$1006=$D$6,IF('P2-Asset Valuation'!$F$7:$F$1006="Confidentiality",'P2-Asset Valuation'!$I$7:$I$1006))),"")} | E12: {=IF(E11<>"",MAX(IF('P2-Asset Valuation'!$E$7:$E$1006=$E$6,IF('P2-Asset Valuation'!$F$7:$F$1006="Confidentiality",'P2-Asset Valuation'!$I$7:$I$1006))),"")} -> 0 | F12: {=IF(F11<>"",MAX(IF('P2-Asset Valuation'!$E$7:$E$1006=$F$6,IF('P2-Asset Valuation'!$F$7:$F$1006="Confidentiality",'P2-Asset Valuation'!$I$7:$I$1006))),"")} | G12: {=IF(G11<>"",MAX(IF('P2-Asset Valuation'!$E$7:$E$1006=$G$6,IF('P2-Asset Valuation'!$F$7:$F$1006="Confidentiality",'P2-Asset Valuation'!$I$7:$I$1006))),"")} | H12: {=IF(H11<>"",MAX(IF('P2-Asset Valuation'!$E$7:$E$1006=$H$6,IF('P2-Asset Valuation'!$F$7:$F$1006="Confidentiality",'P2-Asset Valuation'!$I$7:$I$1006))),"")} | I12: {=IF(I11<>"",MAX(IF('P2-Asset Valuation'!$E$7:$E$1006=$I$6,IF('P2-Asset Valuation'!$F$7:$F$1006="Confidentiality",'P2-Asset Valuation'!$I$7:$I$1006))),"")} | J12: {=IF(J11<>"",MAX(IF('P2-Asset Valuation'!$E$7:$E$1006=$J$6,IF('P2-Asset Valuation'!$F$7:$F$1006="Confidentiality",'P2-Asset Valuation'!$I$7:$I$1006))),"")} | K12: {=IF(K11<>"",MAX(IF('P2-Asset Valuation'!$E$7:$E$1006=$K$6,IF('P2-Asset Valuation'!$F$7:$F$1006="Confidentiality",'P2-Asset Valuation'!$I$7:$I$1006))),"")} -> 0 | L12: {=IF(L11<>"",MAX(IF('P2-Asset Valuation'!$E$7:$E$1006=$L$6,IF('P2-Asset Valuation'!$F$7:$F$1006="Confidentiality",'P2-Asset Valuation'!$I$7:$I$1006))),"")} -> 0 | M12: {=IF(M11<>"",MAX(IF('P2-Asset Valuation'!$E$7:$E$1006=$M$6,IF('P2-Asset Valuation'!$F$7:$F$1006="Confidentiality",'P2-Asset Valuation'!$I$7:$I$1006))),"")} | N12: C | O12: =SUM(D12:M12) -> 0
C13: I | D13: {=IF(D11<>"",MAX(IF('P2-Asset Valuation'!$E$7:$E$1006=$D$6,IF('P2-Asset Valuation'!$F$7:$F$1006="Integrity",'P2-Asset Valuation'!$I$7:$I$1006))),"")} | E13: {=IF(E11<>"",MAX(IF('P2-Asset Valuation'!$E$7:$E$1006=$E$6,IF('P2-Asset Valuation'!$F$7:$F$1006="Integrity",'P2-Asset Valuation'!$I$7:$I$1006))),"")} -> 0 | F13: {=IF(F11<>"",MAX(IF('P2-Asset Valuation'!$E$7:$E$1006=$F$6,IF('P2-Asset Valuation'!$F$7:$F$1006="Integrity",'P2-Asset Valuation'!$I$7:$I$1006))),"")} | G13: {=IF(G11<>"",MAX(IF('P2-Asset Valuation'!$E$7:$E$1006=$G$6,IF('P2-Asset Valuation'!$F$7:$F$1006="Integrity",'P2-Asset Valuation'!$I$7:$I$1006))),"")} | H13: {=IF(H11<>"",MAX(IF('P2-Asset Valuation'!$E$7:$E$1006=$H$6,IF('P2-Asset Valuation'!$F$7:$F$1006="Integrity",'P2-Asset Valuation'!$I$7:$I$1006))),"")} | I13: {=IF(I11<>"",MAX(IF('P2-Asset Valuation'!$E$7:$E$1006=$I$6,IF('P2-Asset Valuation'!$F$7:$F$1006="Integrity",'P2-Asset Valuation'!$I$7:$I$1006))),"")} | J13: {=IF(J11<>"",MAX(IF('P2-Asset Valuation'!$E$7:$E$1006=$J$6,IF('P2-Asset Valuation'!$F$7:$F$1006="Integrity",'P2-Asset Valuation'!$I$7:$I$1006))),"")} | K13: {=IF(K11<>"",MAX(IF('P2-Asset Valuation'!$E$7:$E$1006=$K$6,IF('P2-Asset Valuation'!$F$7:$F$1006="Integrity",'P2-Asset Valuation'!$I$7:$I$1006))),"")} -> 0 | L13: {=IF(L11<>"",MAX(IF('P2-Asset Valuation'!$E$7:$E$1006=$L$6,IF('P2-Asset Valuation'!$F$7:$F$1006="Integrity",'P2-Asset Valuation'!$I$7:$I$1006))),"")} -> 0 | M13: {=IF(M11<>"",MAX(IF('P2-Asset Valuation'!$E$7:$E$1006=$M$6,IF('P2-Asset Valuation'!$F$7:$F$1006="Integrity",'P2-Asset Valuation'!$I$7:$I$1006))),"")} | N13: I | O13: =SUM(D13:M13) -> 0
